const f = () => {
    try {
       let a = 0;
      console.log(program)
      console.log("program run successfully")
      return
    }
    catch(err) {
      console.log("this is an error")
      console.log(p)
    }
    finally{
      console.log("i am good boy")
    }
    }